Workbook

Sheet Báo cáo tổng kết
A1: BÁO CÁO TỔNG KẾT KIỂM THỬ (Test Summary Report)
A3: Mã báo cáo | B3: ACBI-TSR-2026-10-14-01
A4: Hệ thống / phiên bản | B4: ACBI, commit 2194ad7
A5: Môi trường | B5: Bản demo Vercel, Gemini + LiteRouter, kho AdventureWorks (xem sheet 'Môi trường kiểm thử')
A6: Ngày lập | B6: 2026-10-14
A7: Người lập | B7: Bui Duc Hoang
A8: Cấu trúc báo cáo | B8: Theo mẫu test summary report (IEEE 829 / ISO 29119-3) và mẫu bảng test case phổ biến
A10: 1. Tóm tắt điều hành
A11: Sau khi chạy lại các ca báo AI bận cho đến khi không còn, mọi ca đều Passed. Các con số trả lời được đối chiếu độc lập với kho dữ liệu. Phân quyền được kiểm tra trên 4 vai trò và cả hai đường truy vấn. Còn giới hạn: hiệu năng khi nhiều người dùng đồng thời phụ thuộc gói AI miễn phí, dự báo chỉ tương đương phương pháp đơn giản trên dữ liệu mẫu, chưa có pentest và dữ liệu thật. Khuyến nghị: thí điểm giới hạn có điều kiện (mục 5).
A13: 2. Kết quả thực thi (Results summary)
A14: Bộ kiểm thử | B14: Tổng số ca | C14: Passed | D14: Failed | E14: Blocked | F14: Not Run | G14: Đã thực thi (Passed + Failed) | H14: Tỷ lệ Passed / đã thực thi | I14: Ghi chú
A15: RAG Text-to-SQL | B15: =COUNTA('RAG'!A2:A25) | C15: =COUNTIF('RAG'!I2:I25,"Passed") | D15: =COUNTIF('RAG'!I2:I25,"Failed") | E15: =COUNTIF('RAG'!I2:I25,"Blocked") | F15: =B15-C15-D15-E15 | G15: =C15+D15 | H15: =IF(G15=0,"",C15/G15) | I15: Gồm 24 ca; ảnh trình duyệt từng ca
A16: Câu hỏi khó (Hard) | B16: =COUNTA('Hard'!A2:A91) | C16: =COUNTIF('Hard'!I2:I91,"Passed") | D16: =COUNTIF('Hard'!I2:I91,"Failed") | E16: =COUNTIF('Hard'!I2:I91,"Blocked") | F16: =B16-C16-D16-E16 | G16: =C16+D16 | H16: =IF(G16=0,"",C16/G16) | I16: Bẫy ảo giác, nhiều ràng buộc, 4 vai trò
A17: So sánh và nhiều yêu cầu (Compare) | B17: =COUNTA('Compare'!A2:A48) | C17: =COUNTIF('Compare'!I2:I48,"Passed") | D17: =COUNTIF('Compare'!I2:I48,"Failed") | E17: =COUNTIF('Compare'!I2:I48,"Blocked") | F17: =B17-C17-D17-E17 | G17: =C17+D17 | H17: =IF(G17=0,"",C17/G17) | I17: So sánh kỳ, nhiều yêu cầu trong một tin nhắn
A18: Phân quyền theo vai trò | B18: =COUNTA('Phân quyền'!A2:A49) | C18: =COUNTIF('Phân quyền'!I2:I49,"Passed") | D18: =COUNTIF('Phân quyền'!I2:I49,"Failed") | E18: =COUNTIF('Phân quyền'!I2:I49,"Blocked") | F18: =B18-C18-D18-E18 | G18: =C18+D18 | H18: =IF(G18=0,"",C18/G18) | I18: 4 vai trò x 12 câu; đường mẫu, RAG, dự báo, tấn công
A19: Tổng | B19: =SUM(B15:B18) | C19: =SUM(C15:C18) | D19: =SUM(D15:D18) | E19: =SUM(E15:E18) | F19: =SUM(F15:F18) | G19: =SUM(G15:G18) | H19: =IF(G19=0,"",C19/G19)
A20: Mẫu số tỷ lệ Passed: số ca đã thực thi (Passed + Failed), Blocked tính riêng, theo cách tính phổ biến của báo cáo thực thi kiểm thử.
A21: Lần chạy đầu tiên (trước khi chạy lại ca báo AI bận):
A22: Passed 145, Failed 1, Blocked (AI bận) 15 trong 161 ca của RAG, Hard, Compare. Chi tiết từng ca ở cột 'Lần chạy đầu' các sheet kiểm thử. Ca Failed ở lần đầu (C23, so sánh Factory A với Factory B): hệ thống đã sửa để chỉ hiển thị hai nhà máy được nêu và ghi rõ phần chưa gồm; bộ đối chiếu ban đầu coi phần lược bỏ có chủ đích là thiếu nhóm nên đã sửa để chấp nhận phần lược bỏ được nêu rõ trong câu trả lời.
A24: 3. Tiêu chí hoàn thành (Exit criteria)
A25: Tiêu chí | B25: Mục tiêu | C25: Thực tế | D25: Kết luận | E25: Ghi chú
A26: Tỷ lệ Passed các bộ RAG, Hard, Compare | B26: 0.95 | C26: =(C15+C16+C17)/(G15+G16+G17) | D26: =IF(C26>=B26,"Đạt","Chưa đạt") | E26: Mẫu số: ca đã thực thi
A27: Ca Blocked ở lần chạy cuối | B27: 0 | C27: =E19 | D27: =IF(C27<=B27,"Đạt","Chưa đạt") | E27: Ca báo AI bận được chạy lại
A28: Kiểm thử phân quyền: tỷ lệ bị chặn đúng | B28: 1 | C28: =H18 | D28: =IF(C28>=B28,"Đạt","Chưa đạt") | E28: Cả đường mẫu và RAG
A29: Hiệu năng: tỷ lệ yêu cầu dưới 15 giây (5 người dùng đồng thời) | B29: 0.95 | C29: ='Đo tải'!J6 | D29: =IF(C29>=B29,"Đạt","Chưa đạt") | E29: Phụ thuộc gói AI miễn phí; xem sheet 'Đo tải'
A31: 4. Phạm vi, sai lệch và hạn chế
A32: • Đã kiểm thử: câu hỏi số liệu theo tuần, ngày, nhà máy, khu vực; câu hỏi khó (bẫy ảo giác, nhiều ràng buộc, 4 vai trò); so sánh kỳ và nhiều yêu cầu; phân quyền; dự báo (backtest); đo tải 5 người dùng; luồng dữ liệu gửi cho AI.
A33: • Chưa kiểm thử: pentest và quét lỗ hổng độc lập; giọng nói trong môi trường thật; giao diện điện thoại; dữ liệu thật của công ty; tải trên 5 người dùng đồng thời; gói AI trả phí.
A34: • Hạn chế của bằng chứng: kịch bản tự động chạy trên một môi trường (bản demo, dữ liệu mẫu); Hard và Compare chạy qua giao diện lập trình, riêng RAG có ảnh trình duyệt; một số ca Hard chỉ kiểm tra trạng thái và nội dung (không có số để đối chiếu).
A35: • Dự báo: trên dữ liệu mẫu, ETS chỉ tương đương phương pháp đơn giản (xem sheet 'Backtest dự báo'); không nên quảng bá độ chính xác.
A36: • Hiệu năng và độ ổn định của AI bị chi phối bởi quota gói miễn phí; con số chốt cần đo lại với gói trả phí.
A38: 5. Kết luận và khuyến nghị
A39: Khuyến nghị: thí điểm giới hạn có điều kiện. Điều kiện: (1) đo lại hiệu năng với gói AI trả phí; (2) pentest độc lập và rà soát chính sách dữ liệu của nhà cung cấp AI (sheet 'Dữ liệu gửi cho AI'); (3) chạy thử với dữ liệu thật và định nghĩa chỉ số do chủ dữ liệu duyệt; (4) chốt chi phí (sheet 'Chi phí'). Không dùng cho môi trường sản xuất hoặc dữ liệu nhạy cảm khi chưa đủ các điều kiện này.
A41: 6. Tài liệu tham chiếu
A42: • ACBI_Technical_Solution_Proposal_v1.1.docx (đề xuất giải pháp, bản đã cập nhật theo hệ thống đã xây)
A43: • ACBI_bai_trinh_bay.docx và bộ slide bảo vệ
A44: • docs/PHASE_3_EXTERNAL_CONTEXT.md (dữ liệu gửi cho AI)
... A48: 7. Cách đọc các chỉ số trong báo cáo này
A49: Tổng số ca | B49: Số ca kiểm thử trong bộ đó. Một ca là một câu hỏi (hoặc một chuỗi câu hỏi nối tiếp) cùng điều kiện đạt.
A50: Passed | B50: Số ca đạt mọi yêu cầu.
...

Sheet Môi trường kiểm thử
A1: Hạng mục | B1: Giá trị
A2: Hệ thống được kiểm thử | B2: ACBI: trợ lý hỏi đáp dữ liệu kinh doanh bằng tiếng Việt
A3: Địa chỉ | B3: https://acbi-liard.vercel.app (bản đang chạy cho demo)
A4: Phiên bản mã nguồn | B4: nhánh main, commit 2194ad7
A5: Backend và giao diện | B5: Python/FastAPI, React/Vite, triển khai Vercel (vùng sin1)
A6: Kho dữ liệu | B6: AdventureWorks trên PostgreSQL (Neon), tài khoản chỉ đọc acbi_ro; dữ liệu mẫu, bảng gán nhà máy giả lập
A7: Ngày dữ liệu | B7: 2025-06-29 (cố định trong dữ liệu mẫu)
A8: Dịch vụ AI | B8: Gemini (nhiều khóa, gói miễn phí) và LiteRouter (gói miễn phí); không dùng Ollama cho kết quả trong báo cáo này
A9: Tài khoản kiểm thử | B9: manager, sales, production_a, it_admin (nút đăng nhập demo, không dùng mật khẩu)
A10: Công cụ kiểm thử | B10: scripts/verify_rag_cases.py, verify_hard_cases.py, verify_compare_multitask.py, kịch bản ma trận phân quyền, đo tải và backtest; đối chiếu số bằng SQL chỉ đọc độc lập (psycopg)
A11: Cách gọi | B11: Qua giao diện lập trình của chính trang web (/api/chat/ask), một hội thoại mới cho mỗi ca; ảnh chụp bằng Chromium khi hỏi trên trang
A12: Ngày thực hiện | B12: 2026-10-14
... A14: Kiểm thử tự động (pytest) | B14: 287 ca, đạt toàn bộ (chạy từ thư mục gốc dự án)
A17: Cách đọc
A18: Mục đích | B18: Ghi lại điều kiện chạy (địa chỉ, phiên bản mã nguồn, dữ liệu, dịch vụ AI, tài khoản, công cụ) để người khác chạy lại và so sánh được kết quả. Đổi một điều kiện (ví dụ gói AI trả phí) thì kết quả có thể khác.

Sheet RAG
A1: Test Case ID | B1: Test Suite | C1: Tiêu đề (Title) | D1: Điều kiện tiên quyết (Pre-conditions) | E1: Các bước (Test Steps) | F1: Dữ liệu kiểm thử (Test Data) | G1: Kết quả mong đợi (Expected Result) | H1: Kết quả thực tế (Actual Result) | I1: Trạng thái (Status) | J1: Lần chạy đầu (First run) | K1: Người thực hiện (Executed by) | L1: Ngày (Date) | M1: Ghi chú và bằng chứng (Comments) | N1: Ảnh trình duyệt (Screenshot)
A2: R01 | B2: RAG Text-to-SQL | C2: Câu hỏi: Doanh thu theo tuần trong tháng 3 năm 2025 | D2: Tài khoản manager, ngôn ngữ vi, hội thoại mới | E2: 1. Gửi câu hỏi lượt 1 và đọc phản hồi 2. Chạy SQL độc lập trên kho dữ liệu (tài khoản chỉ đọc) và so với câu trả lời | F2: 1. Doanh thu theo tuần trong tháng 3 năm 2025 | G2: Lượt 1: Trạng thái cho phép: ok | H2: Lượt 1: [ok] Doanh thu từ 01/03/2025 đến 31/03/2025: 6 nhóm. Cao nhất là 24/03/2025 (3.767.708,93), thấp nhất là 31/03/2025 (34.544,95). Từ 24/02/2025 đến 31/03/2025, doanh thu giảm 70,9%. (số dòng 6, biểu đồ line) | I2: Passed | J2: Passed | K2: Kịch bản tự động (scripts/verify_*.py) | L2: 2026-10-14 | M2: SQL kho dữ liệu: SELECT date_trunc('week',h.orderdate)::date,SUM(h.subtotal) FROM sales.salesorderheader h JOIN sales.salesterritory t ON t.territoryid=h.territoryid WHERE h.orderdate>=%s AND h.orderdate<%s AND (%s::text IS NULL OR t.name=%s) GROUP BY 1 | tham số: 2025-03-01, 2025-04-01, None, None | kết quả: 6 dòng, đầu: [['2025-03-31', '34544.9500'], ['2025-02-24', '118746.1600'], ['2025-03-17', '411465.7000'], ['2025-03-10', '308973.2000']] Đối chiếu độc lập (chính): KHỚP 6/6 giá trị. SQL: SELECT date_trunc('week',h.orderdate)::date,SUM(h.subtotal) FROM sales.salesorderheader h JOIN sales.salesterritory t ON t.territoryid=h.territoryid WHERE h.orderdate>=%s AND h.orderdate<%s GROUP BY date_trunc('week',h.orderdate)::date | tham số: 2025-03-01, 2025-04-01
A3: R02 | B3: RAG Text-to-SQL | C3: Câu hỏi: Sản lượng theo tuần trong quý 1 năm 2025 | D3: Tài khoản manager, ngôn ngữ vi, hội thoại mới | E3: 1. Gửi câu hỏi lượt 1 và đọc phản hồi 2. Chạy SQL độc lập trên kho dữ liệu (tài khoản chỉ đọc) và so với câu trả lời | F3: 1. Sản lượng theo tuần trong quý 1 năm 2025 | G3: Lượt 1: Trạng thái cho phép: ok | H3: Lượt 1: [ok] Sản lượng từ 01/01/2025 đến 31/03/2025: 14 nhóm. Cao nhất là 10/02/2025 (142.852,00), thấp nhất là 31/03/2025 (2.479,00). Từ 30/12/2024 đến 31/03/2025, sản lượng giảm 52,0%. (số dòng 14, biểu đồ line) | I3: Passed | J3: Passed | K3: Kịch bản tự động (scripts/verify_*.py) | L3: 2026-10-14 | M3: SQL kho dữ liệu: SELECT date_trunc('week',w.enddate)::date,SUM(w.orderqty-w.scrappedqty) FROM production.workorder w WHERE w.enddate>=%s AND w.enddate<%s GROUP BY 1 | tham số: 2025-01-01, 2025-04-01 | kết quả: 14 dòng, đầu: [['2025-03-31', '2479'], ['2025-02-24', '8544'], ['2025-01-20', '8346'], ['2025-02-17', '8500']] Đối chiếu độc lập (chính): KHỚP 14/14 giá trị. SQL: WITH terminal AS (SELECT DISTINCT ON (workorderid) workorderid,locationid FROM production.workorderrouting ORDER BY workorderid,operationsequence DESC,locationid),fact AS (SELECT w.*,f.factory_id AS fid,COALESCE(f.name,'Unassigned') AS fname FROM production.workorder w LEFT JOIN terminal t ON t.workorderid=w.workorderid LEFT JOIN acbi_demo.location_factory lf ON lf.locationid=t.locationid LEFT JOIN acbi_demo.factory f ON f.factory_id=lf.factory_id) SELECT date_trunc('week',enddate)::date,SUM(orderqty-scrappedqty) FROM fact WHERE enddate>=%s AND enddate<%s GROUP BY date_trunc('week',enddate)::d | tham số: 2025-01-01, 2025-04-01
A4: R03 | B4: RAG Text-to-SQL | C4: Câu hỏi: Sản lượng theo ngày trong tháng 3 năm 2025 | D4: Tài khoản manager, ngôn ngữ vi, hội thoại mới | E4: 1. Gửi câu hỏi lượt 1 và đọc phản hồi 2. Chạy SQL độc lập trên kho dữ liệu (tài khoản chỉ đọc) và so với câu trả lời | F4: 1. Sản lượng theo ngày trong tháng 3 năm 2025 | G4: Lượt 1: Trạng thái cho phép: ok | H4: Lượt 1: [ok] Sản lượng từ 01/03/2025 đến 31/03/2025: 31 nhóm. Cao nhất là 13/03/2025 (83.382,00), thấp nhất là 10/03/2025 (654,00). Từ 01/03/2025 đến 31/03/2025, sản lượng tăng 38,8%. (số dòng 31, biểu đồ line) | I4: Passed | J4: Blocked | K4: Kịch bản tự động (scripts/verify_*.py) | L4: 2026-10-14 | M4: SQL kho dữ liệu: SELECT w.enddate::date,SUM(w.orderqty-w.scrappedqty) FROM production.workorder w WHERE w.enddate>=%s AND w.enddate<%s GROUP BY 1 | tham số: 2025-03-01, 2025-04-01 | kết quả: 31 dòng, đầu: [['2025-03-31', '2479'], ['2025-03-16', '1405'], ['2025-03-20', '1234'], ['2025-03-18', '1182']] Đối chiếu độc lập (chính): KHỚP 31/31 giá trị. SQL: WITH terminal AS (SELECT DISTINCT ON (workorderid) workorderid,locationid FROM production.workorderrouting ORDER BY workorderid,operationsequence DESC,locationid),fact AS (SELECT w.*,f.factory_id AS fid,COALESCE(f.name,'Unassigned') AS fname FROM production.workorder w LEFT JOIN terminal t ON t.workorderid=w.workorderid LEFT JOIN acbi_demo.location_factory lf ON lf.locationid=t.locationid LEFT JOIN acbi_demo.factory f ON f.factory_id=lf.factory_id) SELECT enddate::date,SUM(orderqty-scrappedqty) FROM fact WHERE enddate>=%s AND enddate<%s GROUP BY enddate::date | tham số: 2025-03-01, 2025-04-01 Lần chạy đầu báo AI bận (quota); chạy lại đến khi không còn báo bận.
A5: R04 | B5: RAG Text-to-SQL | C5: Câu hỏi: Sản lượng của Factory A theo từng ngày trong tháng 3 năm 2025 | D5: Tài khoản manager, ngôn ngữ vi, hội thoại mới | E5: 1. Gửi câu hỏi lượt 1 và đọc phản hồi 2. Chạy SQL độc lập trên kho dữ liệu (tài khoản chỉ đọc) và so với câu trả lời | F5: 1. Sản lượng của Factory A theo từng ngày trong tháng 3 năm 2025 | G5: Lượt 1: Trạng thái cho phép: ok | H5: Lượt 1: [ok] Sản lượng (Factory A) từ 01/03/2025 đến 31/03/2025: 21 nhóm. Cao nhất là 19/03/2025 (20.163,00), thấp nhất là 16/03/2025 (207,00). Từ 01/03/2025 đến 31/03/2025, sản lượng tăng 54,5%. (số dòng 21, biểu đồ line) | I5: Passed | J5: Blocked | K5: Kịch bản tự động (scripts/verify_*.py) | L5: 2026-10-14 | M5: SQL kho dữ liệu: SELECT w.enddate::date,SUM(w.orderqty-w.scrappedqty) FROM production.workorder w WHERE w.enddate>=%s AND w.enddate<%s AND w.workorderid IN (SELECT terminal.workorderid FROM (SELECT DISTINCT ON (workorderid) workorderid,locationid FROM production.workorderrouting ORDER BY workorderid,operationsequence DESC,locationid) terminal JOIN acbi_demo.location_factory lf USING(locationid) WHERE lf.factory_id | tham số: 2025-03-01, 2025-04-01 | kết quả: 21 dòng, đầu: [['2025-03-01', '594'], ['2025-03-03', '270'], ['2025-03-04', '315'], ['2025-03-05', '612']] Đối chiếu độc lập (chính): KHỚP 21/21 giá trị. SQL: WITH terminal AS (SELECT DISTINCT ON (workorderid) workorderid,locationid FROM production.workorderrouting ORDER BY workorderid,operationsequence DESC,locationid),fact AS (SELECT w.*,f.factory_id AS fid,COALESCE(f.name,'Unassigned') AS fname FROM production.workorder w LEFT JOIN terminal t ON t.workorderid=w.workorderid LEFT JOIN acbi_demo.location_factory lf ON lf.locationid=t.locationid LEFT JOIN acbi_demo.factory f ON f.factory_id=lf.factory_id) SELECT enddate::date,SUM(orderqty-scrappedqty) FROM fact WHERE enddate>=%s AND enddate<%s AND fid=%s GROUP BY enddate::date | tham số: 2025-03-01, 2025-04-01, 1 Lần chạy đầu báo AI bận (quota); chạy lại đến khi không còn báo bận.
A6: R05 | B6: RAG Text-to-SQL | C6: Câu hỏi: Tỷ lệ lỗi theo ngày trong tháng 3 năm 2025 | D6: Tài khoản manager, ngôn ngữ vi, hội thoại mới | E6: 1. Gửi câu hỏi lượt 1 và đọc phản hồi 2. Chạy SQL độc lập trên kho dữ liệu (tài khoản chỉ đọc) và so với câu trả lời | F6: 1. Tỷ lệ lỗi theo ngày trong tháng 3 năm 2025 | G6: Lượt 1: Trạng thái cho phép: ok | H6: Lượt 1: [ok] Tỷ lệ phế phẩm từ 01/03/2025 đến 31/03/2025: 31 nhóm. Cao nhất là 09/03/2025 (0,6%), thấp nhất là 31/03/2025 (0,0%). (số dòng 31, biểu đồ line) | I6: Passed | J6: Blocked | K6: Kịch bản tự động (scripts/verify_*.py) | L6: 2026-10-14 | M6: SQL kho dữ liệu: SELECT w.enddate::date,SUM(w.scrappedqty)::numeric/NULLIF(SUM(w.orderqty),0) FROM production.workorder w WHERE w.enddate>=%s AND w.enddate<%s GROUP BY 1 | tham số: 2025-03-01, 2025-04-01 | kết quả: 31 dòng, đầu: [['2025-03-31', '0E-20'], ['2025-03-16', '0.00142146410803127221'], ['2025-03-20', '0.00080971659919028340'], ['2025-03-18', '0.00337268128161888702']] Đối chiếu độc lập (chính): KHỚP 31/31 giá trị. SQL: WITH terminal AS (SELECT DISTINCT ON (workorderid) workorderid,locationid FROM production.workorderrouting ORDER BY workorderid,operationsequence DESC,locationid),fact AS (SELECT w.*,f.factory_id AS fid,COALESCE(f.name,'Unassigned') AS fname FROM production.workorder w LEFT JOIN terminal t ON t.workorderid=w.workorderid LEFT JOIN acbi_demo.location_factory lf ON lf.locationid=t.locationid LEFT JOIN acbi_demo.factory f ON f.factory_id=lf.factory_id) SELECT enddate::date,SUM(scrappedqty)::numeric/NULLIF(SUM(orderqty),0) FROM fact WHERE enddate>=%s AND enddate<%s GROUP BY enddate::date | tham số: 2025-03-01, 2025-04-01 Lần chạy đầu báo AI bận (quota); chạy lại đến khi không còn báo bận.
A7: R06 | B7: RAG Text-to-SQL | C7: Câu hỏi: Tỷ lệ lỗi theo tuần trong quý 1 năm 2025 | D7: Tài khoản manager, ngôn ngữ vi, hội thoại mới | E7: 1. Gửi câu hỏi lượt 1 và đọc phản hồi 2. Chạy SQL độc lập trên kho dữ liệu (tài khoản chỉ đọc) và so với câu trả lời | F7: 1. Tỷ lệ lỗi theo tuần trong quý 1 năm 2025 | G7: Lượt 1: Trạng thái cho phép: ok | H7: Lượt 1: [ok] Tỷ lệ phế phẩm từ 01/01/2025 đến 31/03/2025: 14 nhóm. Cao nhất là 13/01/2025 (0,3%), thấp nhất là 31/03/2025 (0,0%). (số dòng 14, biểu đồ line) | I7: Passed | J7: Blocked | K7: Kịch bản tự động (scripts/verify_*.py) | L7: 2026-10-14 | M7: SQL kho dữ liệu: SELECT date_trunc('week',w.enddate)::date,SUM(w.scrappedqty)::numeric/NULLIF(SUM(w.orderqty),0) FROM production.workorder w WHERE w.enddate>=%s AND w.enddate<%s GROUP BY 1 | tham số: 2025-01-01, 2025-04-01 | kết quả: 14 dòng, đầu: [['2025-03-31', '0E-20'], ['2025-02-24', '0E-20'], ['2025-01-20', '0.00239062873535739900'], ['2025-02-17', '0.00187881634570220761']] Đối chiếu độc lập (chính): KHỚP 14/14 giá trị. SQL: WITH terminal AS (SELECT DISTINCT ON (workorderid) workorderid,locationid FROM production.workorderrouting ORDER BY workorderid,operationsequence DESC,locationid),fact AS (SELECT w.*,f.factory_id AS fid,COALESCE(f.name,'Unassigned') AS fname FROM production.workorder w LEFT JOIN terminal t ON t.workorderid=w.workorderid LEFT JOIN acbi_demo.location_factory lf ON lf.locationid=t.locationid LEFT JOIN acbi_demo.factory f ON f.factory_id=lf.factory_id) SELECT date_trunc('week',enddate)::date,SUM(scrappedqty)::numeric/NULLIF(SUM(orderqty),0) FROM fact WHERE enddate>=%s AND enddate<%s GROUP BY date_ | tham số: 2025-01-01, 2025-04-01 Lần chạy đầu báo AI bận (quota); chạy lại đến khi không còn báo bận.
A8: R07 | B8: RAG Text-to-SQL | C8: Câu hỏi: Doanh thu của Canada theo tuần trong tháng 3 năm 2025 | D8: Tài khoản manager, ngôn ngữ vi, hội thoại mới | E8: 1. Gửi câu hỏi lượt 1 và đọc phản hồi 2. Chạy SQL độc lập trên kho dữ liệu (tài khoản chỉ đọc) và so với câu trả lời | F8: 1. Doanh thu của Canada theo tuần trong tháng 3 năm 2025 | G8: Lượt 1: Trạng thái cho phép: ok | H8: Lượt 1: [ok] Doanh thu (Canada) từ 01/03/2025 đến 31/03/2025: 6 nhóm. Cao nhất là 24/03/2025 (430.127,57), thấp nhất là 31/03/2025 (5.392,70). Từ 24/02/2025 đến 31/03/2025, doanh thu giảm 31,7%. (số dòng 6, biểu đồ line) | I8: Passed | J8: Blocked | K8: Kịch bản tự động (scripts/verify_*.py) | L8: 2026-10-14 | M8: SQL kho dữ liệu: SELECT date_trunc('week',h.orderdate)::date,SUM(h.subtotal) FROM sales.salesorderheader h JOIN sales.salesterritory t ON t.territoryid=h.territoryid WHERE h.orderdate>=%s AND h.orderdate<%s AND (%s::text IS NULL OR t.name=%s) GROUP BY 1 | tham số: 2025-03-01, 2025-04-01, Canada, Canada | kết quả: 6 dòng, đầu: [['2025-02-24', '7896.1800'], ['2025-03-03', '16142.2500'], ['2025-03-10', '28319.8600'], ['2025-03-17', '21137.1300']] Đối chiếu độc lập (chính): KHỚP 6/6 giá trị. SQL: SELECT date_trunc('week',h.orderdate)::date,SUM(h.subtotal) FROM sales.salesorderheader h JOIN sales.salesterritory t ON t.territoryid=h.territoryid WHERE h.orderdate>=%s AND h.orderdate<%s AND t.name = ANY(%s) GROUP BY date_trunc('week',h.orderdate)::date | tham số: 2025-03-01, 2025-04-01, ['Canada'] Lần chạy đầu báo AI bận (quota); chạy lại đến khi không còn báo bận.
A9: R08 | B9: RAG Text-to-SQL | C9: Câu hỏi: Sản lượng Factory A theo tuần trong quý 1 năm 2025 | D9: Tài khoản manager, ngôn ngữ vi, hội thoại mới | E9: 1. Gửi câu hỏi lượt 1 và đọc phản hồi 2. Chạy SQL độc lập trên kho dữ liệu (tài khoản chỉ đọc) và so với câu trả lời | F9: 1. Sản lượng Factory A theo tuần trong quý 1 năm 2025 | G9: Lượt 1: Trạng thái cho phép: ok | H9: Lượt 1: [ok] Sản lượng (Factory A) từ 01/01/2025 đến 31/03/2025: 14 nhóm. Cao nhất là 10/02/2025 (28.250,00), thấp nhất là 30/12/2024 (882,00). Từ 30/12/2024 đến 31/03/2025, sản lượng tăng 4,1%. (số dòng 14, biểu đồ line) | I9: Passed | J9: Passed | K9: Kịch bản tự động (scripts/verify_*.py) | L9: 2026-10-14 | M9: SQL kho dữ liệu: SELECT date_trunc('week',w.enddate)::date,SUM(w.orderqty-w.scrappedqty) FROM production.workorder w WHERE w.enddate>=%s AND w.enddate<%s AND w.workorderid IN (SELECT terminal.workorderid FROM (SELECT DISTINCT ON (workorderid) workorderid,locationid FROM production.workorderrouting ORDER BY workorderid,operationsequence DESC,locationid) terminal JOIN acbi_demo.location_factory lf USING(locationid) | tham số: 2025-01-01, 2025-04-01 | kết quả: 14 dòng, đầu: [['2024-12-30', '882'], ['2025-01-06', '2151'], ['2025-01-13', '26378'], ['2025-01-20', '1665']] Đối chiếu độc lập (chính): KHỚP 14/14 giá trị. SQL: WITH terminal AS (SELECT DISTINCT ON (workorderid) workorderid,locationid FROM production.workorderrouting ORDER BY workorderid,operationsequence DESC,locationid),fact AS (SELECT w.*,f.factory_id AS fid,COALESCE(f.name,'Unassigned') AS fname FROM production.workorder w LEFT JOIN terminal t ON t.workorderid=w.workorderid LEFT JOIN acbi_demo.location_factory lf ON lf.locationid=t.locationid LEFT JOIN acbi_demo.factory f ON f.factory_id=lf.factory_id) SELECT date_trunc('week',enddate)::date,SUM(orderqty-scrappedqty) FROM fact WHERE enddate>=%s AND enddate<%s AND fid=%s GROUP BY date_trunc('week', | tham số: 2025-01-01, 2025-04-01, 1
A10: R09 | B10: RAG Text-to-SQL | C10: Câu hỏi: Doanh thu theo tuần trong quý 1 năm 2025 | D10: Tài khoản manager, ngôn ngữ vi, hội thoại mới | E10: 1. Gửi câu hỏi lượt 1 và đọc phản hồi 2. Chạy SQL độc lập trên kho dữ liệu (tài khoản chỉ đọc) và so với câu trả lời | F10: 1. Doanh thu theo tuần trong quý 1 năm 2025 | G10: Lượt 1: Trạng thái cho phép: ok | H10: Lượt 1: [ok] Doanh thu từ 01/01/2025 đến 31/03/2025: 14 nhóm. Cao nhất là 24/03/2025 (3.767.708,93), thấp nhất là 31/03/2025 (34.544,95). Từ 30/12/2024 đến 31/03/2025, doanh thu giảm 87,6%. (số dòng 14, biểu đồ line) | I10: Passed | J10: Blocked | K10: Kịch bản tự động (scripts/verify_*.py) | L10: 2026-10-14 | M10: SQL kho dữ liệu: SELECT date_trunc('week',h.orderdate)::date,SUM(h.subtotal) FROM sales.salesorderheader h JOIN sales.salesterritory t ON t.territoryid=h.territoryid WHERE h.orderdate>=%s AND h.orderdate<%s AND (%s::text IS NULL OR t.name=%s) GROUP BY 1 | tham số: 2025-01-01, 2025-04-01, None, None | kết quả: 14 dòng, đầu: [['2025-03-31', '34544.9500'], ['2025-02-24', '2568715.3433'], ['2025-01-20', '317685.3000'], ['2025-02-17', '320732.7700']] Đối chiếu độc lập (chính): KHỚP 14/14 giá trị. SQL: SELECT date_trunc('week',h.orderdate)::date,SUM(h.subtotal) FROM sales.salesorderheader h JOIN sales.salesterritory t ON t.territoryid=h.territoryid WHERE h.orderdate>=%s AND h.orderdate<%s GROUP BY date_trunc('week',h.orderdate)::date | tham số: 2025-01-01, 2025-04-01 Lần chạy đầu báo AI bận (quota); chạy lại đến khi không còn báo bận.
A11: R10 | B11: RAG Text-to-SQL | C11: Câu hỏi: Sản lượng theo ngày trong tháng 3 năm 2025 | D11: Tài khoản production_a, ngôn ngữ vi, hội thoại mới | E11: 1. Gửi câu hỏi lượt 1 và đọc phản hồi 2. Chạy SQL độc lập trên kho dữ liệu (tài khoản chỉ đọc) và so với câu trả lời | F11: 1. Sản lượng theo ngày trong tháng 3 năm 2025 | G11: Lượt 1: Trạng thái cho phép: ok | H11: Lượt 1: [ok] Sản lượng từ 01/03/2025 đến 31/03/2025: 21 nhóm. Cao nhất là 19/03/2025 (20.163,00), thấp nhất là 16/03/2025 (207,00). Từ 01/03/2025 đến 31/03/2025, sản lượng tăng 54,5%. (số dòng 21, biểu đồ line) | I11: Passed | J11: Passed | K11: Kịch bản tự động (scripts/verify_*.py) | L11: 2026-10-14 | M11: SQL kho dữ liệu: SELECT w.enddate::date,SUM(w.orderqty-w.scrappedqty) FROM production.workorder w WHERE w.enddate>=%s AND w.enddate<%s AND w.workorderid IN (SELECT terminal.workorderid FROM (SELECT DISTINCT ON (workorderid) workorderid,locationid FROM production.workorderrouting ORDER BY workorderid,operationsequence DESC,locationid) terminal JOIN acbi_demo.location_factory lf USING(locationid) WHERE lf.factory_id | tham số: 2025-03-01, 2025-04-01 | kết quả: 21 dòng, đầu: [['2025-03-01', '594'], ['2025-03-03', '270'], ['2025-03-04', '315'], ['2025-03-05', '612']] Đối chiếu độc lập (chính): KHỚP 21/21 giá trị. SQL: WITH terminal AS (SELECT DISTINCT ON (workorderid) workorderid,locationid FROM production.workorderrouting ORDER BY workorderid,operationsequence DESC,locationid),fact AS (SELECT w.*,f.factory_id AS fid,COALESCE(f.name,'Unassigned') AS fname FROM production.workorder w LEFT JOIN terminal t ON t.workorderid=w.workorderid LEFT JOIN acbi_demo.location_factory lf ON lf.locationid=t.locationid LEFT JOIN acbi_demo.factory f ON f.factory_id=lf.factory_id) SELECT enddate::date,SUM(orderqty-scrappedqty) FROM fact WHERE enddate>=%s AND enddate<%s AND fid=%s GROUP BY enddate::date | tham số: 2025-03-01, 2025-04-01, 1
A12: R11 | B12: RAG Text-to-SQL | C12: Câu hỏi: Sản lượng theo tuần trong quý 1 năm 2025 | D12: Tài khoản sales, ngôn ngữ vi, hội thoại mới | E12: 1. Gửi câu hỏi lượt 1 và đọc phản hồi | F12: 1. Sản lượng theo tuần trong quý 1 năm 2025 | G12: Lượt 1: Trạng thái cho phép: denied | H12: Lượt 1: [denied] Data is outside your access scope (số dòng 0, biểu đồ không) | I12: Passed | J12: Passed | K12: Kịch bản tự động (scripts/verify_*.py) | L12: 2026-10-14 | M12: (kiểm tra trạng thái và nội dung, không có số để đối chiếu)
A13: R12 | B13: RAG Text-to-SQL | C13: Câu hỏi: Doanh thu theo tuần trong tháng 3 năm 2025 | D13: Tài khoản production_a, ngôn ngữ vi, hội thoại mới | E13: 1. Gửi câu hỏi lượt 1 và đọc phản hồi | F13: 1. Doanh thu theo tuần trong tháng 3 năm 2025 | G13: Lượt 1: Trạng thái cho phép: denied | H13: Lượt 1: [denied] Data is outside your access scope (số dòng 0, biểu đồ không) | I13: Passed | J13: Passed | K13: Kịch bản tự động (scripts/verify_*.py) | L13: 2026-10-14 | M13: (kiểm tra trạng thái và nội dung, không có số để đối chiếu)
... A25: R24 | B25: RAG Text-to-SQL | C25: Câu hỏi: Sản lượng Factory A theo tuần trong tháng 6 năm 2025 | D25: Tài khoản manager, ngôn ngữ vi, hội thoại mới | E25: 1. Gửi câu hỏi lượt 1 và đọc phản hồi 2. Chạy SQL độc lập trên kho dữ liệu (tài khoản chỉ đọc) và so với câu trả lời | F25: 1. Sản lượng Factory A theo tuần trong tháng 6 năm 2025 | G25: Lượt 1: Trạng thái cho phép: ok | H25: Lượt 1: [ok] Sản lượng (Factory A) từ 01/06/2025 đến 30/06/2025: 3 nhóm. Cao nhất là 02/06/2025 (3.069,00), thấp nhất là 16/06/2025 (738,00). Từ 02/06/2025 đến 16/06/2025, sản lượng giảm 76,0%. (số dòng 3, biểu đồ bar) | I25: Passed | J25: Passed | K25: Kịch bản tự động (scripts/verify_*.py) | L25: 2026-10-14 | M25: SQL kho dữ liệu: SELECT date_trunc('week',w.enddate)::date,SUM(w.orderqty-w.scrappedqty) FROM production.workorder w WHERE w.enddate>=%s AND w.enddate<%s AND w.workorderid IN (SELECT terminal.workorderid FROM (SELECT DISTINCT ON (workorderid) workorderid,locationid FROM production.workorderrouting ORDER BY workorderid,operationsequence DESC,locationid) terminal JOIN acbi_demo.location_factory lf USING(locationid) | tham số: 2025-06-01, 2025-06-30 | kết quả: 3 dòng, đầu: [['2025-06-02', '3069'], ['2025-06-09', '1952'], ['2025-06-16', '738']] Đối chiếu độc lập (chính): KHỚP 3/3 giá trị. SQL: WITH terminal AS (SELECT DISTINCT ON (workorderid) workorderid,locationid FROM production.workorderrouting ORDER BY workorderid,operationsequence DESC,locationid),fact AS (SELECT w.*,f.factory_id AS fid,COALESCE(f.name,'Unassigned') AS fname FROM production.workorder w LEFT JOIN terminal t ON t.workorderid=w.workorderid LEFT JOIN acbi_demo.location_factory lf ON lf.locationid=t.locationid LEFT JOIN acbi_demo.factory f ON f.factory_id=lf.factory_id) SELECT date_trunc('week',enddate)::date,SUM(orderqty-scrappedqty) FROM fact WHERE enddate>=%s AND enddate<%s AND fid=%s GROUP BY date_trunc('week', | tham số: 2025-06-01, 2025-07-01, 1
A28: Cách đọc các cột
A29: Test Case ID | D29: Mã của ca kiểm thử (ví dụ R01, H12, M3). Dùng mã này để tìm lại ca trong kịch bản chạy và trong báo cáo.
A30: Test Suite | D30: Nhóm (bộ) kiểm thử mà ca thuộc về.
A31: Tiêu đề (Title) | D31: Tên ngắn của ca: câu hỏi chính được đem ra thử.
A32: Điều kiện tiên quyết (Pre-conditions) | D32: Cần có gì trước khi chạy: đăng nhập bằng vai trò nào, ngôn ngữ nào, hội thoại mới hay nhiều lượt trong cùng một hội thoại.
A33: Các bước (Test Steps) | D33: Việc đã làm, theo thứ tự: gửi từng câu hỏi, rồi (nếu có) chạy một câu SQL độc lập trên kho dữ liệu để đối chiếu số.
A34: Dữ liệu kiểm thử (Test Data) | D34: Nguyên văn các câu hỏi đã gửi cho hệ thống.
A35: Kết quả mong đợi (Expected Result) | D35: Điều hệ thống phải làm để ca được coi là đạt: trạng thái cho phép (ok = có số liệu, needs_clarification = hỏi lại, denied = từ chối, no_data = không có dữ liệu), số dòng, loại biểu đồ, cụm chữ phải có hoặc không được có, và số có khớp kho dữ liệu hay không.
A36: Kết quả thực tế (Actual Result) | D36: Điều hệ thống đã trả về: trạng thái, câu trả lời nguyên văn (cắt ngắn), số dòng của bảng và loại biểu đồ.
A37: Trạng thái (Status) | D37: Passed = đạt mọi yêu cầu. Failed = có yêu cầu sai. Blocked = không chạy được vì dịch vụ AI báo bận (hết hạn mức), không phải lỗi của hệ thống. Not Run = chưa chạy.
A38: Lần chạy đầu (First run) | D38: Kết quả ở lần chạy đầu tiên. Ca báo Blocked ở lần đầu được chạy lại cho đến khi không còn báo bận, nên cột Trạng thái là kết quả cuối còn cột này giữ dấu vết lần đầu.
A39: Người thực hiện / Ngày | D39: Ai hoặc cái gì chạy ca (kịch bản tự động) và chạy ngày nào.
A40: Ghi chú và bằng chứng (Comments) | D40: Bằng chứng cho kết quả: câu SQL độc lập chạy trên kho dữ liệu, tham số và kết quả của nó (để so với con số trong câu trả lời). Với tin nhắn nhiều yêu cầu: kết quả từng phần.
A41: Ảnh trình duyệt (Screenshot) | D41: Ảnh chụp trang web thật sau khi hỏi đúng câu này (chỉ sheet RAG).

Sheet Hard
A1: Test Case ID | B1: Test Suite | C1: Tiêu đề (Title) | D1: Điều kiện tiên quyết (Pre-conditions) | E1: Các bước (Test Steps) | F1: Dữ liệu kiểm thử (Test Data) | G1: Kết quả mong đợi (Expected Result) | H1: Kết quả thực tế (Actual Result) | I1: Trạng thái (Status) | J1: Lần chạy đầu (First run) | K1: Người thực hiện (Executed by) | L1: Ngày (Date) | M1: Ghi chú và bằng chứng (Comments)
A2: H01 | B2: Câu hỏi khó | C2: Câu hỏi: Lợi nhuận năm 2024 là bao nhiêu? | D2: Tài khoản manager, ngôn ngữ vi, hội thoại mới | E2: 1. Gửi câu hỏi lượt 1 và đọc phản hồi | F2: 1. Lợi nhuận năm 2024 là bao nhiêu? | G2: Lượt 1: Trạng thái cho phép: needs_clarification; Không có dòng dữ liệu; Không được bịa số | H2: Lượt 1: [needs_clarification] Hệ thống không thể báo cáo lợi nhuận. Các chỉ số được phép là: Sản lượng, Tỷ lệ phế phẩm, Tỷ lệ hoàn thành đúng hạn, Doanh thu và Tăng trưởng doanh thu. Tôi có thể báo cáo Doanh thu cho năm 2024 nếu bạn muốn. (số dòng 0, biểu đồ không) | I2: Passed | J2: Passed | K2: Kịch bản tự động (scripts/verify_*.py) | L2: 2026-10-14 | M2: (kiểm tra trạng thái và nội dung, không có số để đối chiếu)
A3: H02 | B3: Câu hỏi khó | C3: Câu hỏi: Số lượng khách hàng mới năm 2024 | D3: Tài khoản manager, ngôn ngữ vi, hội thoại mới | E3: 1. Gửi câu hỏi lượt 1 và đọc phản hồi | F3: 1. Số lượng khách hàng mới năm 2024 | G3: Lượt 1: Trạng thái cho phép: needs_clarification; Không có dòng dữ liệu; Không được bịa số | H3: Lượt 1: [needs_clarification] Hệ thống không thể cung cấp số lượng khách hàng mới năm 2024. Các chỉ số được phép báo cáo chỉ bao gồm sản lượng, tỷ lệ phế phẩm, tỷ lệ hoàn thành đúng hạn, doanh thu và tăng trưởng doanh thu. Tôi không có thông tin về số lượng khách hàng. Tôi có thể báo cáo … (số dòng 0, biểu đồ không) | I3: Passed | J3: Passed | K3: Kịch bản tự động (scripts/verify_*.py) | L3: 2026-10-14 | M3: (kiểm tra trạng thái và nội dung, không có số để đối chiếu)
A4: H03 | B4: Câu hỏi khó | C4: Câu hỏi: Tồn kho hiện tại của xe đạp Mountain | D4: Tài khoản manager, ngôn ngữ vi, hội thoại mới | E4: 1. Gửi câu hỏi lượt 1 và đọc phản hồi | F4: 1. Tồn kho hiện tại của xe đạp Mountain | G4: Lượt 1: Trạng thái cho phép: needs_clarification; Không có dòng dữ liệu; Không được bịa số | H4: Lượt 1: [needs_clarification] Hệ thống không thể báo cáo tồn kho vì không có số liệu tồn kho trong danh sách các chỉ số được phép. Các chỉ số có sẵn là Sản lượng, Tỷ lệ phế phẩm, Tỷ lệ hoàn thành đúng hạn, Doanh thu và Tăng trưởng doanh thu. Bạn có thể hỏi về sản lượng sản xuất hoặc doanh… (số dòng 0, biểu đồ không) | I4: Passed | J4: Passed | K4: Kịch bản tự động (scripts/verify_*.py) | L4: 2026-10-14 | M4: (kiểm tra trạng thái và nội dung, không có số để đối chiếu)
A5: H04 | B5: Câu hỏi khó | C5: Câu hỏi: Doanh thu ở Nhật Bản năm 2024 | D5: Tài khoản manager, ngôn ngữ vi, hội thoại mới | E5: 1. Gửi câu hỏi lượt 1 và đọc phản hồi | F5: 1. Doanh thu ở Nhật Bản năm 2024 | G5: Lượt 1: Trạng thái cho phép: needs_clarification; Không có dòng dữ liệu; Không được bịa số | H5: Lượt 1: [needs_clarification] Tôi không nhận ra khu vực này. Các khu vực có dữ liệu: Australia, Canada, Central, France, Germany, Northeast, Northwest, Southeast, Southwest, United Kingdom. (số dòng 0, biểu đồ không) | I5: Passed | J5: Passed | K5: Kịch bản tự động (scripts/verify_*.py) | L5: 2026-10-14 | M5: (kiểm tra trạng thái và nội dung, không có số để đối chiếu)
A6: H05 | B6: Câu hỏi khó | C6: Câu hỏi: Doanh thu tại Hà Nội quý trước | D6: Tài khoản manager, ngôn ngữ vi, hội thoại mới | E6: 1. Gửi câu hỏi lượt 1 và đọc phản hồi | F6: 1. Doanh thu tại Hà Nội quý trước | G6: Lượt 1: Trạng thái cho phép: needs_clarification; Không có dòng dữ liệu; Không được bịa số | H6: Lượt 1: [needs_clarification] Tôi không nhận ra khu vực này. Các khu vực có dữ liệu: Australia, Canada, Central, France, Germany, Northeast, Northwest, Southeast, Southwest, United Kingdom. (số dòng 0, biểu đồ không) | I6: Passed | J6: Passed | K6: Kịch bản tự động (scripts/verify_*.py) | L6: 2026-10-14 | M6: (kiểm tra trạng thái và nội dung, không có số để đối chiếu)
A7: H06 | B7: Câu hỏi khó | C7: Câu hỏi: Sản lượng Factory D năm 2024 | D7: Tài khoản manager, ngôn ngữ vi, hội thoại mới | E7: 1. Gửi câu hỏi lượt 1 và đọc phản hồi | F7: 1. Sản lượng Factory D năm 2024 | G7: Lượt 1: Trạng thái cho phép: needs_clarification; Không có dòng dữ liệu; Không được bịa số | H7: Lượt 1: [needs_clarification] Tôi không có nhà máy đó. Các nhà máy có dữ liệu: Factory A, Factory B, Factory C. (số dòng 0, biểu đồ không) | I7: Passed | J7: Blocked | K7: Kịch bản tự động (scripts/verify_*.py) | L7: 2026-10-14 | M7: Lần chạy đầu báo AI bận (quota); chạy lại đến khi không còn báo bận.
A8: H07 | B8: Câu hỏi khó | C8: Câu hỏi: Sản lượng nhà máy số 7 năm 2024 | D8: Tài khoản manager, ngôn ngữ vi, hội thoại mới | E8: 1. Gửi câu hỏi lượt 1 và đọc phản hồi | F8: 1. Sản lượng nhà máy số 7 năm 2024 | G8: Lượt 1: Trạng thái cho phép: needs_clarification; Không có dòng dữ liệu; Không được bịa số | H8: Lượt 1: [needs_clarification] Tôi không có nhà máy đó. Các nhà máy có dữ liệu: Factory A, Factory B, Factory C. (số dòng 0, biểu đồ không) | I8: Passed | J8: Blocked | K8: Kịch bản tự động (scripts/verify_*.py) | L8: 2026-10-14 | M8: Lần chạy đầu báo AI bận (quota); chạy lại đến khi không còn báo bận.
A9: H08 | B9: Câu hỏi khó | C9: Câu hỏi: Doanh thu năm 2019 | D9: Tài khoản manager, ngôn ngữ vi, hội thoại mới | E9: 1. Gửi câu hỏi lượt 1 và đọc phản hồi | F9: 1. Doanh thu năm 2019 | G9: Lượt 1: Trạng thái cho phép: no_data, needs_clarification; Không có dòng dữ liệu; Không được bịa số | H9: Lượt 1: [no_data] Không có dữ liệu doanh thu từ 01/01/2019 đến 31/12/2019. (số dòng 0, biểu đồ không) | I9: Passed | J9: Passed | K9: Kịch bản tự động (scripts/verify_*.py) | L9: 2026-10-14 | M9: (kiểm tra trạng thái và nội dung, không có số để đối chiếu)
A10: H09 | B10: Câu hỏi khó | C10: Câu hỏi: Doanh thu tháng 1 năm 2030 | D10: Tài khoản manager, ngôn ngữ vi, hội thoại mới | E10: 1. Gửi câu hỏi lượt 1 và đọc phản hồi | F10: 1. Doanh thu tháng 1 năm 2030 | G10: Lượt 1: Trạng thái cho phép: no_data, needs_clarification; Không có dòng dữ liệu; Không được bịa số | H10: Lượt 1: [no_data] Không có dữ liệu doanh thu từ 01/01/2030 đến 31/01/2030. (số dòng 0, biểu đồ không) | I10: Passed | J10: Passed | K10: Kịch bản tự động (scripts/verify_*.py) | L10: 2026-10-14 | M10: (kiểm tra trạng thái và nội dung, không có số để đối chiếu)
A11: H10 | B11: Câu hỏi khó | C11: Câu hỏi: Doanh thu quý 4 năm 2026 là bao nhiêu? | D11: Tài khoản manager, ngôn ngữ vi, hội thoại mới | E11: 1. Gửi câu hỏi lượt 1 và đọc phản hồi | F11: 1. Doanh thu quý 4 năm 2026 là bao nhiêu? | G11: Lượt 1: Trạng thái cho phép: no_data, needs_clarification; Không có dòng dữ liệu; Không được bịa số | H11: Lượt 1: [no_data] Không có dữ liệu doanh thu từ 01/10/2026 đến 31/12/2026. (số dòng 0, biểu đồ không) | I11: Passed | J11: Passed | K11: Kịch bản tự động (scripts/verify_*.py) | L11: 2026-10-14 | M11: (kiểm tra trạng thái và nội dung, không có số để đối chiếu)
A12: H11 | B12: Câu hỏi khó | C12: Câu hỏi: Tại sao doanh thu quý trước giảm? | D12: Tài khoản manager, ngôn ngữ vi, hội thoại mới | E12: 1. Gửi câu hỏi lượt 1 và đọc phản hồi 2. Chạy SQL độc lập trên kho dữ liệu (tài khoản chỉ đọc) và so với câu trả lời | F12: 1. Tại sao doanh thu quý trước giảm? | G12: Lượt 1: Trạng thái cho phép: needs_clarification, ok; has_any: nguyên nhân, giải thích, reasons, explain; Số liệu khớp kho dữ liệu (đối chiếu bằng SQL độc lập) | H12: Lượt 1: [ok] Doanh thu từ 01/01/2025 đến 31/03/2025: 12.830.208,58 đơn vị tiền tệ nguồn. Tôi chỉ đưa ra số liệu, chưa giải thích được nguyên nhân. (số dòng 1, biểu đồ kpi_card) | I12: Passed | J12: Passed | K12: Kịch bản tự động (scripts/verify_*.py) | L12: 2026-10-14 | M12: SQL kho dữ liệu: SELECT COALESCE(SUM(h.subtotal),0) FROM sales.salesorderheader h JOIN sales.salesterritory t ON t.territoryid=h.territoryid WHERE h.orderdate>=%s AND h.orderdate<%s AND (%s::text IS NULL OR t.name=%s) | tham số: 2025-01-01, 2025-04-01, None, None | kết quả: 1 dòng, đầu: [['12830208.5790']] Đối chiếu độc lập (chính): KHỚP 1/1 giá trị. SQL: SELECT 'all',SUM(h.subtotal) FROM sales.salesorderheader h JOIN sales.salesterritory t ON t.territoryid=h.territoryid WHERE h.orderdate>=%s AND h.orderdate<%s | tham số: 2025-01-01, 2025-04-01
... A91: X12 | B91: Câu hỏi khó | C91: Câu hỏi: Doanh thu, sản lượng và tỷ lệ phế phẩm quý 1 năm 2025 của Canada | D91: Tài khoản manager, ngôn ngữ vi, hội thoại mới | E91: 1. Gửi câu hỏi lượt 1 và đọc phản hồi | F91: 1. Doanh thu, sản lượng và tỷ lệ phế phẩm quý 1 năm 2025 của Canada | G91: Lượt 1: Trạng thái cho phép: ok, needs_clarification | H91: Lượt 1: [ok] Doanh thu từ 01/01/2025 đến 31/12/2025: 20.008.518,36 đơn vị tiền tệ nguồn. (số dòng 1, biểu đồ kpi_card) | I91: Passed | J91: Passed | K91: Kịch bản tự động (scripts/verify_*.py) | L91: 2026-10-14 | M91: Các phần của tin nhắn: 2. Sản lượng năm 2025: [ok] Sản lượng từ 01/01/2025 đến 31/12/2025: 924.633,00 sản phẩm. | 3. Tỷ lệ phế phẩm quý 1 năm 2025 của Canada: [needs_clarification] Sản lượng và phế phẩm không gắn với khu vực bán hàng. Bạn có thể hỏi theo nhà máy hoặc dây chuyền. Đối chiếu độc lập (chính): KHỚP 1/1 giá trị. SQL: SELECT 'all',SUM(h.subtotal) FROM sales.salesorderheader h JOIN sales.salesterritory t ON t.territoryid=h.territoryid WHERE h.orderdate>=%s AND h.orderdate<%s | tham số: 2025-01-01, 2026-01-01 Đối chiếu độc lập (2. Sản lượng năm 2025): KHỚP 1/1 giá trị. SQL: WITH terminal AS (SELECT DISTINCT ON (workorderid) workorderid,locationid FROM production.workorderrouting ORDER BY workorderid,operationsequence DESC,locationid),fact AS (SELECT w.*,f.factory_id AS fid,COALESCE(f.name,'Unassigned') AS fname FROM production.workorder w LEFT JOIN terminal t ON t.workorderid=w.workorderid LEFT JOIN acbi_demo.location_factory lf ON lf.locationid=t.locationid LEFT JOIN acbi_demo.factory f ON f.factory_id=lf.factory_id) SELECT 'all',SUM(orderqty-scrappedqty) FROM fact WHERE enddate>=%s AND enddate<%s | tham số: 2025-01-01, 2026-01-01
A94: Cách đọc các cột
A95: Test Case ID | D95: Mã của ca kiểm thử (ví dụ R01, H12, M3). Dùng mã này để tìm lại ca trong kịch bản chạy và trong báo cáo.
A96: Test Suite | D96: Nhóm (bộ) kiểm thử mà ca thuộc về.
A97: Tiêu đề (Title) | D97: Tên ngắn của ca: câu hỏi chính được đem ra thử.
A98: Điều kiện tiên quyết (Pre-conditions) | D98: Cần có gì trước khi chạy: đăng nhập bằng vai trò nào, ngôn ngữ nào, hội thoại mới hay nhiều lượt trong cùng một hội thoại.
A99: Các bước (Test Steps) | D99: Việc đã làm, theo thứ tự: gửi từng câu hỏi, rồi (nếu có) chạy một câu SQL độc lập trên kho dữ liệu để đối chiếu số.
A100: Dữ liệu kiểm thử (Test Data) | D100: Nguyên văn các câu hỏi đã gửi cho hệ thống.
A101: Kết quả mong đợi (Expected Result) | D101: Điều hệ thống phải làm để ca được coi là đạt: trạng thái cho phép (ok = có số liệu, needs_clarification = hỏi lại, denied = từ chối, no_data = không có dữ liệu), số dòng, loại biểu đồ, cụm chữ phải có hoặc không được có, và số có khớp kho dữ liệu hay không.
A102: Kết quả thực tế (Actual Result) | D102: Điều hệ thống đã trả về: trạng thái, câu trả lời nguyên văn (cắt ngắn), số dòng của bảng và loại biểu đồ.
A103: Trạng thái (Status) | D103: Passed = đạt mọi yêu cầu. Failed = có yêu cầu sai. Blocked = không chạy được vì dịch vụ AI báo bận (hết hạn mức), không phải lỗi của hệ thống. Not Run = chưa chạy.
A104: Lần chạy đầu (First run) | D104: Kết quả ở lần chạy đầu tiên. Ca báo Blocked ở lần đầu được chạy lại cho đến khi không còn báo bận, nên cột Trạng thái là kết quả cuối còn cột này giữ dấu vết lần đầu.
A105: Người thực hiện / Ngày | D105: Ai hoặc cái gì chạy ca (kịch bản tự động) và chạy ngày nào.
A106: Ghi chú và bằng chứng (Comments) | D106: Bằng chứng cho kết quả: câu SQL độc lập chạy trên kho dữ liệu, tham số và kết quả của nó (để so với con số trong câu trả lời). Với tin nhắn nhiều yêu cầu: kết quả từng phần.
A107: Nhiều lượt hỏi | D107: Ca có nhiều lượt: các lượt được đánh số trong cột Các bước, Dữ liệu, Mong đợi và Thực tế, theo cùng thứ tự.

Sheet Compare
A1: Test Case ID | B1: Test Suite | C1: Tiêu đề (Title) | D1: Điều kiện tiên quyết (Pre-conditions) | E1: Các bước (Test Steps) | F1: Dữ liệu kiểm thử (Test Data) | G1: Kết quả mong đợi (Expected Result) | H1: Kết quả thực tế (Actual Result) | I1: Trạng thái (Status) | J1: Lần chạy đầu (First run) | K1: Người thực hiện (Executed by) | L1: Ngày (Date) | M1: Ghi chú và bằng chứng (Comments)
A2: C1 | B2: So sánh và nhiều yêu cầu | C2: Câu hỏi: so sánh doanh thu canada năm 2023 và 2024 | D2: Tài khoản manager, ngôn ngữ vi, hội thoại mới | E2: 1. Gửi câu hỏi lượt 1 và đọc phản hồi 2. Chạy SQL độc lập trên kho dữ liệu (tài khoản chỉ đọc) và so với câu trả lời | F2: 1. so sánh doanh thu canada năm 2023 và 2024 | G2: Lượt 1: Trạng thái cho phép: ok; Số dòng: 2; Biểu đồ: bar; Câu trả lời phải có: Canada, tăng; Có cột: period | H2: Lượt 1: [ok] Doanh thu (Canada): Năm 2023: 5.580.848,05; Năm 2024: 6.231.209,96. Năm 2024 tăng 11,7% so với Năm 2023. (số dòng 2, biểu đồ bar) | I2: Passed | J2: Passed | K2: Kịch bản tự động (scripts/verify_*.py) | L2: 2026-10-14 | M2: SQL kho dữ liệu: SELECT SUM(h.subtotal) FROM sales.salesorderheader h JOIN sales.salesterritory t ON t.territoryid=h.territoryid WHERE h.orderdate>=%s AND h.orderdate<%s AND t.name=%s | tham số: 2023-01-01, 2024-01-01, Canada | kết quả: 1 dòng, đầu: [['5580848.0456']] SQL kho dữ liệu: SELECT SUM(h.subtotal) FROM sales.salesorderheader h JOIN sales.salesterritory t ON t.territoryid=h.territoryid WHERE h.orderdate>=%s AND h.orderdate<%s AND t.name=%s | tham số: 2024-01-01, 2025-01-01, Canada | kết quả: 1 dòng, đầu: [['6231209.9635']] Đối chiếu độc lập (chính): KHỚP 2/2 giá trị. SQL: SELECT 'all',SUM(h.subtotal) FROM sales.salesorderheader h JOIN sales.salesterritory t ON t.territoryid=h.territoryid WHERE h.orderdate>=%s AND h.orderdate<%s AND t.name = ANY(%s) | tham số: 2024-01-01, 2025-01-01, ['Canada']
A3: C2 | B3: So sánh và nhiều yêu cầu | C3: Câu hỏi: so sánh doanh thu Canada và France năm 2023 và 2024 | D3: Tài khoản manager, ngôn ngữ vi, hội thoại mới | E3: 1. Gửi câu hỏi lượt 1 và đọc phản hồi | F3: 1. so sánh doanh thu Canada và France năm 2023 và 2024 | G3: Lượt 1: Trạng thái cho phép: ok; Số dòng: 2; Biểu đồ: bar; Có cột: territory, Năm 2023, Năm 2024 | H3: Lượt 1: [ok] Doanh thu, 2 nhóm, Năm 2023 – Năm 2024. Đứng đầu Năm 2024: Canada (6.231.209,96). Tăng mạnh nhất: France (+145,1%); thấp nhất: Canada (+11,7%). Không nhóm nào giảm. Tổng thay đổi +2.909.752,31; đóng góp nhiều nhất: France (+2.259.390,39, 77,6% tổng thay đổi). (số dòng 2, biểu đồ bar) | I3: Passed | J3: Passed | K3: Kịch bản tự động (scripts/verify_*.py) | L3: 2026-10-14 | M3: Đối chiếu độc lập (chính): KHỚP 6/6 giá trị. SQL: SELECT t.name,SUM(h.subtotal) FROM sales.salesorderheader h JOIN sales.salesterritory t ON t.territoryid=h.territoryid WHERE h.orderdate>=%s AND h.orderdate<%s GROUP BY t.name | tham số: 2024-01-01, 2025-01-01
A4: C3 | B4: So sánh và nhiều yêu cầu | C4: Câu hỏi: compare revenue Q1 2024 and Q1 2025 | D4: Tài khoản manager, ngôn ngữ en, hội thoại mới | E4: 1. Gửi câu hỏi lượt 1 và đọc phản hồi 2. Chạy SQL độc lập trên kho dữ liệu (tài khoản chỉ đọc) và so với câu trả lời | F4: 1. compare revenue Q1 2024 and Q1 2025 | G4: Lượt 1: Trạng thái cho phép: ok; Số dòng: 2; Biểu đồ: bar; Câu trả lời phải có: Q1 2024, Q1 2025, up | H4: Lượt 1: [ok] Revenue: Q1 2024: 7,838,170.11; Q1 2025: 12,830,208.58. Q1 2025 is up 63.7% against Q1 2024. (số dòng 2, biểu đồ bar) | I4: Passed | J4: Passed | K4: Kịch bản tự động (scripts/verify_*.py) | L4: 2026-10-14 | M4: SQL kho dữ liệu: SELECT SUM(h.subtotal) FROM sales.salesorderheader h JOIN sales.salesterritory t ON t.territoryid=h.territoryid WHERE h.orderdate>=%s AND h.orderdate<%s | tham số: 2024-01-01, 2024-04-01 | kết quả: 1 dòng, đầu: [['7838170.1074']] SQL kho dữ liệu: SELECT SUM(h.subtotal) FROM sales.salesorderheader h JOIN sales.salesterritory t ON t.territoryid=h.territoryid WHERE h.orderdate>=%s AND h.orderdate<%s | tham số: 2025-01-01, 2025-04-01 | kết quả: 1 dòng, đầu: [['12830208.5790']] Đối chiếu độc lập (chính): KHỚP 2/2 giá trị. SQL: SELECT 'all',SUM(h.subtotal) FROM sales.salesorderheader h JOIN sales.salesterritory t ON t.territoryid=h.territoryid WHERE h.orderdate>=%s AND h.orderdate<%s | tham số: 2025-01-01, 2025-04-01
A5: C4 | B5: So sánh và nhiều yêu cầu | C5: Câu hỏi: so sánh doanh thu quý 1 và quý 2 năm 2025 | D5: Tài khoản manager, ngôn ngữ vi, hội thoại mới | E5: 1. Gửi câu hỏi lượt 1 và đọc phản hồi 2. Chạy SQL độc lập trên kho dữ liệu (tài khoản chỉ đọc) và so với câu trả lời | F5: 1. so sánh doanh thu quý 1 và quý 2 năm 2025 | G5: Lượt 1: Trạng thái cho phép: ok; Số dòng: 2; Biểu đồ: bar; Câu trả lời phải có: Quý 1/2025, Quý 2/2025 | H5: Lượt 1: [ok] Doanh thu: Quý 1/2025: 12.830.208,58; Quý 2/2025: 7.178.309,78. Quý 2/2025 giảm 44,1% so với Quý 1/2025. (số dòng 2, biểu đồ bar) | I5: Passed | J5: Passed | K5: Kịch bản tự động (scripts/verify_*.py) | L5: 2026-10-14 | M5: SQL kho dữ liệu: SELECT SUM(h.subtotal) FROM sales.salesorderheader h JOIN sales.salesterritory t ON t.territoryid=h.territoryid WHERE h.orderdate>=%s AND h.orderdate<%s | tham số: 2025-01-01, 2025-04-01 | kết quả: 1 dòng, đầu: [['12830208.5790']] SQL kho dữ liệu: SELECT SUM(h.subtotal) FROM sales.salesorderheader h JOIN sales.salesterritory t ON t.territoryid=h.territoryid WHERE h.orderdate>=%s AND h.orderdate<%s | tham số: 2025-04-01, 2025-07-01 | kết quả: 1 dòng, đầu: [['7178309.7823']] Đối chiếu độc lập (chính): KHỚP 2/2 giá trị. SQL: SELECT 'all',SUM(h.subtotal) FROM sales.salesorderheader h JOIN sales.salesterritory t ON t.territoryid=h.territoryid WHERE h.orderdate>=%s AND h.orderdate<%s | tham số: 2025-04-01, 2025-07-01
A6: C5 | B6: So sánh và nhiều yêu cầu | C6: Câu hỏi: so sánh doanh thu tháng 1, tháng 2 và tháng 3 năm 2025 | D6: Tài khoản manager, ngôn ngữ vi, hội thoại mới | E6: 1. Gửi câu hỏi lượt 1 và đọc phản hồi 2. Chạy SQL độc lập trên kho dữ liệu (tài khoản chỉ đọc) và so với câu trả lời | F6: 1. so sánh doanh thu tháng 1, tháng 2 và tháng 3 năm 2025 | G6: Lượt 1: Trạng thái cho phép: ok; Số dòng: 3; Biểu đồ: bar; Câu trả lời phải có: Tháng 1/2025, Tháng 3/2025 | H6: Lượt 1: [ok] Doanh thu: Tháng 1/2025: 4.276.427,72; Tháng 2/2025: 3.565.879,32; Tháng 3/2025: 4.987.901,53. Tháng 3/2025 tăng 16,6% so với Tháng 1/2025. (số dòng 3, biểu đồ bar) | I6: Passed | J6: Passed | K6: Kịch bản tự động (scripts/verify_*.py) | L6: 2026-10-14 | M6: SQL kho dữ liệu: SELECT SUM(h.subtotal) FROM sales.salesorderheader h JOIN sales.salesterritory t ON t.territoryid=h.territoryid WHERE h.orderdate>=%s AND h.orderdate<%s | tham số: 2025-01-01, 2025-02-01 | kết quả: 1 dòng, đầu: [['4276427.7214']] SQL kho dữ liệu: SELECT SUM(h.subtotal) FROM sales.salesorderheader h JOIN sales.salesterritory t ON t.territoryid=h.territoryid WHERE h.orderdate>=%s AND h.orderdate<%s | tham số: 2025-02-01, 2025-03-01 | kết quả: 1 dòng, đầu: [['3565879.3233']] SQL kho dữ liệu: SELECT SUM(h.subtotal) FROM sales.salesorderheader h JOIN sales.salesterritory t ON t.territoryid=h.territoryid WHERE h.orderdate>=%s AND h.orderdate<%s | tham số: 2025-03-01, 2025-04-01 | kết quả: 1 dòng, đầu: [['4987901.5343']] Đối chiếu độc lập (chính): KHỚP 3/3 giá trị. SQL: SELECT 'all',SUM(h.subtotal) FROM sales.salesorderheader h JOIN sales.salesterritory t ON t.territoryid=h.territoryid WHERE h.orderdate>=%s AND h.orderdate<%s | tham số: 2025-03-01, 2025-04-01
A7: C6 | B7: So sánh và nhiều yêu cầu | C7: Câu hỏi: so sánh sản lượng năm 2023 và 2024 | D7: Tài khoản manager, ngôn ngữ vi, hội thoại mới | E7: 1. Gửi câu hỏi lượt 1 và đọc phản hồi | F7: 1. so sánh sản lượng năm 2023 và 2024 | G7: Lượt 1: Trạng thái cho phép: ok; Số dòng: 2; Biểu đồ: bar; Câu trả lời phải có: Sản lượng | H7: Lượt 1: [ok] Sản lượng: Năm 2023: 1.300.267,00; Năm 2024: 1.896.377,00. Năm 2024 tăng 45,8% so với Năm 2023. (số dòng 2, biểu đồ bar) | I7: Passed | J7: Passed | K7: Kịch bản tự động (scripts/verify_*.py) | L7: 2026-10-14 | M7: Đối chiếu độc lập (chính): KHỚP 2/2 giá trị. SQL: WITH terminal AS (SELECT DISTINCT ON (workorderid) workorderid,locationid FROM production.workorderrouting ORDER BY workorderid,operationsequence DESC,locationid),fact AS (SELECT w.*,f.factory_id AS fid,COALESCE(f.name,'Unassigned') AS fname FROM production.workorder w LEFT JOIN terminal t ON t.workorderid=w.workorderid LEFT JOIN acbi_demo.location_factory lf ON lf.locationid=t.locationid LEFT JOIN acbi_demo.factory f ON f.factory_id=lf.factory_id) SELECT 'all',SUM(orderqty-scrappedqty) FROM fact WHERE enddate>=%s AND enddate<%s | tham số: 2024-01-01, 2025-01-01
A8: C7 | B8: So sánh và nhiều yêu cầu | C8: Câu hỏi: so sánh tỷ lệ phế phẩm theo nhà máy năm 2023 và 2024 | D8: Tài khoản manager, ngôn ngữ vi, hội thoại mới | E8: 1. Gửi câu hỏi lượt 1 và đọc phản hồi | F8: 1. so sánh tỷ lệ phế phẩm theo nhà máy năm 2023 và 2024 | G8: Lượt 1: Trạng thái cho phép: ok; Số dòng: 2, 4; Biểu đồ: bar; Có cột: factory, Năm 2023, Năm 2024 | H8: Lượt 1: [ok] Tỷ lệ phế phẩm, 3 nhóm, Năm 2023 – Năm 2024. Đứng đầu Năm 2024: Unassigned (0,3%). Tăng mạnh nhất: Unassigned (+30,1%); thấp nhất: Factory A (+11,7%). Không nhóm nào giảm. Tổng thay đổi +0,1%; đóng góp nhiều nhất: Unassigned (+0,1%, 55,6% tổng thay đổi). (số dòng 3, biểu đồ bar) | I8: Passed | J8: Passed | K8: Kịch bản tự động (scripts/verify_*.py) | L8: 2026-10-14 | M8: Đối chiếu độc lập (chính): KHỚP 9/9 giá trị. SQL: WITH terminal AS (SELECT DISTINCT ON (workorderid) workorderid,locationid FROM production.workorderrouting ORDER BY workorderid,operationsequence DESC,locationid),fact AS (SELECT w.*,f.factory_id AS fid,COALESCE(f.name,'Unassigned') AS fname FROM production.workorder w LEFT JOIN terminal t ON t.workorderid=w.workorderid LEFT JOIN acbi_demo.location_factory lf ON lf.locationid=t.locationid LEFT JOIN acbi_demo.factory f ON f.factory_id=lf.factory_id) SELECT fname,SUM(scrappedqty)::numeric/NULLIF(SUM(orderqty),0) FROM fact WHERE enddate>=%s AND enddate<%s GROUP BY fname | tham số: 2024-01-01, 2025-01-01
A9: C8 | B9: So sánh và nhiều yêu cầu | C9: Câu hỏi: so sánh doanh thu theo danh mục sản phẩm năm 2023 và 2024 | D9: Tài khoản manager, ngôn ngữ vi, hội thoại mới | E9: 1. Gửi câu hỏi lượt 1 và đọc phản hồi | F9: 1. so sánh doanh thu theo danh mục sản phẩm năm 2023 và 2024 | G9: Lượt 1: Trạng thái cho phép: ok; Số dòng: 3, 6; Biểu đồ: bar; Có cột: category | H9: Lượt 1: [ok] Doanh thu, 4 nhóm, Năm 2023 – Năm 2024. Đứng đầu Năm 2024: Bikes (36.313.572,48). Tăng mạnh nhất: Accessories (+574,8%); thấp nhất: Bikes (+33,7%). Không nhóm nào giảm. Tổng thay đổi +12.066.967,56; đóng góp nhiều nhất: Bikes (+9.161.021,41, 75,9% tổng thay đ… (số dòng 4, biểu đồ bar) | I9: Passed | J9: Passed | K9: Kịch bản tự động (scripts/verify_*.py) | L9: 2026-10-14 | M9: Đối chiếu độc lập (chính): chưa đối chiếu (chiều so sánh (ví dụ ngành hàng) không có truy vấn đối chiếu độc lập)
A10: C9 | B10: So sánh và nhiều yêu cầu | C10: Câu hỏi: so sánh doanh thu năm 2023 và 2024 theo tháng | D10: Tài khoản manager, ngôn ngữ vi, hội thoại mới | E10: 1. Gửi câu hỏi lượt 1 và đọc phản hồi | F10: 1. so sánh doanh thu năm 2023 và 2024 theo tháng | G10: Lượt 1: Trạng thái cho phép: ok; Số dòng: 24; Biểu đồ: line | H10: Lượt 1: [ok] Doanh thu từ 01/01/2023 đến 31/12/2024: 24 nhóm. Cao nhất là tháng 06/2024 (5.063.798,38), thấp nhất là tháng 02/2023 (1.449.883,20). Từ tháng 01/2023 đến tháng 12/2024, doanh thu tăng 96,6%. Đây là kết quả cho cả khoảng thời gian liền nhau bạn nêu. (số dòng 24, biểu đồ line) | I10: Passed | J10: Passed | K10: Kịch bản tự động (scripts/verify_*.py) | L10: 2026-10-14 | M10: Đối chiếu độc lập (chính): KHỚP 24/24 giá trị. SQL: SELECT date_trunc('month',h.orderdate)::date,SUM(h.subtotal) FROM sales.salesorderheader h JOIN sales.salesterritory t ON t.territoryid=h.territoryid WHERE h.orderdate>=%s AND h.orderdate<%s GROUP BY date_trunc('month',h.orderdate)::date | tham số: 2023-01-01, 2025-01-01
A11: C10 | B11: So sánh và nhiều yêu cầu | C11: Câu hỏi: so sánh doanh thu năm 2023 và 2024 bằng biểu đồ tròn | D11: Tài khoản manager, ngôn ngữ vi, hội thoại mới | E11: 1. Gửi câu hỏi lượt 1 và đọc phản hồi | F11: 1. so sánh doanh thu năm 2023 và 2024 bằng biểu đồ tròn | G11: Lượt 1: Trạng thái cho phép: ok; Số dòng: 2; Biểu đồ: pie | H11: Lượt 1: [ok] Doanh thu: Năm 2023: 31.604.921,95; Năm 2024: 43.671.889,50. Năm 2024 tăng 38,2% so với Năm 2023. (số dòng 2, biểu đồ pie) | I11: Passed | J11: Passed | K11: Kịch bản tự động (scripts/verify_*.py) | L11: 2026-10-14 | M11: Đối chiếu độc lập (chính): KHỚP 2/2 giá trị. SQL: SELECT 'all',SUM(h.subtotal) FROM sales.salesorderheader h JOIN sales.salesterritory t ON t.territoryid=h.territoryid WHERE h.orderdate>=%s AND h.orderdate<%s | tham số: 2024-01-01, 2025-01-01
A12: C11 | B12: So sánh và nhiều yêu cầu | C12: Câu hỏi: so sánh doanh thu của Wakanda năm 2023 và 2024 | D12: Tài khoản manager, ngôn ngữ vi, hội thoại mới | E12: 1. Gửi câu hỏi lượt 1 và đọc phản hồi | F12: 1. so sánh doanh thu của Wakanda năm 2023 và 2024 | G12: Lượt 1: Trạng thái cho phép: needs_clarification | H12: Lượt 1: [needs_clarification] Tôi không nhận ra khu vực này. Các khu vực có dữ liệu: Australia, Canada, Central, France, Germany, Northeast, Northwest, Southeast, Southwest, United Kingdom. (số dòng 0, biểu đồ không) | I12: Passed | J12: Passed | K12: Kịch bản tự động (scripts/verify_*.py) | L12: 2026-10-14 | M12: (kiểm tra trạng thái và nội dung, không có số để đối chiếu)
... A48: M17 | B48: So sánh và nhiều yêu cầu | C48: Câu hỏi: Doanh thu năm 2024 theo khu vực và tỷ lệ phế phẩm năm 2024 | D48: Tài khoản manager, ngôn ngữ vi, hội thoại mới, các lượt trong cùng một hội thoại | E48: 1. Gửi câu hỏi lượt 1 và đọc phản hồi 2. Gửi câu hỏi lượt 2 và đọc phản hồi | F48: 1. Doanh thu năm 2024 theo khu vực và tỷ lệ phế phẩm năm 2024 2. còn Canada thì sao? | G48: Lượt 1: Trạng thái cho phép: ok; Số phần: {'status': 'ok'} Lượt 2: Trạng thái cho phép: ok | H48: Lượt 1: [ok] Doanh thu từ 01/01/2024 đến 31/12/2024: 10 nhóm. Cao nhất là Southwest (9.121.931,65), thấp nhất là Southeast (2.399.947,38). Southwest chiếm 20,9% trong tổng 43.671.889,50. (số dòng 10, biểu đồ bar) Lượt 2: [ok] Doanh thu của Canada từ 01/01/2024 đến 31/12/2024: 6.231.209,96 đơn vị tiền tệ nguồn. (số dòng 1, biểu đồ kpi_card) | I48: Passed | J48: Passed | K48: Kịch bản tự động (scripts/verify_*.py) | L48: 2026-10-14 | M48: Các phần của tin nhắn: 2. Tỷ lệ phế phẩm năm 2024: [ok] Tỷ lệ phế phẩm từ 01/01/2024 đến 31/12/2024: 0,29%. Đối chiếu độc lập (chính): KHỚP 10/10 giá trị. SQL: SELECT t.name,SUM(h.subtotal) FROM sales.salesorderheader h JOIN sales.salesterritory t ON t.territoryid=h.territoryid WHERE h.orderdate>=%s AND h.orderdate<%s GROUP BY t.name | tham số: 2024-01-01, 2025-01-01 Đối chiếu độc lập (2. Tỷ lệ phế phẩm năm 2024): KHỚP 1/1 giá trị. SQL: WITH terminal AS (SELECT DISTINCT ON (workorderid) workorderid,locationid FROM production.workorderrouting ORDER BY workorderid,operationsequence DESC,locationid),fact AS (SELECT w.*,f.factory_id AS fid,COALESCE(f.name,'Unassigned') AS fname FROM production.workorder w LEFT JOIN terminal t ON t.workorderid=w.workorderid LEFT JOIN acbi_demo.location_factory lf ON lf.locationid=t.locationid LEFT JOIN acbi_demo.factory f ON f.factory_id=lf.factory_id) SELECT 'all',SUM(scrappedqty)::numeric/NULLIF(SUM(orderqty),0) FROM fact WHERE enddate>=%s AND enddate<%s | tham số: 2024-01-01, 2025-01-01 Đối chiếu độc lập (chính): KHỚP 1/1 giá trị. SQL: SELECT 'all',SUM(h.subtotal) FROM sales.salesorderheader h JOIN sales.salesterritory t ON t.territoryid=h.territoryid WHERE h.orderdate>=%s AND h.orderdate<%s AND t.name = ANY(%s) | tham số: 2024-01-01, 2025-01-01, ['Canada']
A51: Cách đọc các cột
A52: Test Case ID | D52: Mã của ca kiểm thử (ví dụ R01, H12, M3). Dùng mã này để tìm lại ca trong kịch bản chạy và trong báo cáo.
A53: Test Suite | D53: Nhóm (bộ) kiểm thử mà ca thuộc về.
A54: Tiêu đề (Title) | D54: Tên ngắn của ca: câu hỏi chính được đem ra thử.
A55: Điều kiện tiên quyết (Pre-conditions) | D55: Cần có gì trước khi chạy: đăng nhập bằng vai trò nào, ngôn ngữ nào, hội thoại mới hay nhiều lượt trong cùng một hội thoại.
A56: Các bước (Test Steps) | D56: Việc đã làm, theo thứ tự: gửi từng câu hỏi, rồi (nếu có) chạy một câu SQL độc lập trên kho dữ liệu để đối chiếu số.
A57: Dữ liệu kiểm thử (Test Data) | D57: Nguyên văn các câu hỏi đã gửi cho hệ thống.
A58: Kết quả mong đợi (Expected Result) | D58: Điều hệ thống phải làm để ca được coi là đạt: trạng thái cho phép (ok = có số liệu, needs_clarification = hỏi lại, denied = từ chối, no_data = không có dữ liệu), số dòng, loại biểu đồ, cụm chữ phải có hoặc không được có, và số có khớp kho dữ liệu hay không.
A59: Kết quả thực tế (Actual Result) | D59: Điều hệ thống đã trả về: trạng thái, câu trả lời nguyên văn (cắt ngắn), số dòng của bảng và loại biểu đồ.
A60: Trạng thái (Status) | D60: Passed = đạt mọi yêu cầu. Failed = có yêu cầu sai. Blocked = không chạy được vì dịch vụ AI báo bận (hết hạn mức), không phải lỗi của hệ thống. Not Run = chưa chạy.
A61: Lần chạy đầu (First run) | D61: Kết quả ở lần chạy đầu tiên. Ca báo Blocked ở lần đầu được chạy lại cho đến khi không còn báo bận, nên cột Trạng thái là kết quả cuối còn cột này giữ dấu vết lần đầu.
A62: Người thực hiện / Ngày | D62: Ai hoặc cái gì chạy ca (kịch bản tự động) và chạy ngày nào.
A63: Ghi chú và bằng chứng (Comments) | D63: Bằng chứng cho kết quả: câu SQL độc lập chạy trên kho dữ liệu, tham số và kết quả của nó (để so với con số trong câu trả lời). Với tin nhắn nhiều yêu cầu: kết quả từng phần.
A64: Các phần của tin nhắn | D64: Một tin nhắn có nhiều yêu cầu được hệ thống tách thành các phần đánh số; kết quả từng phần nằm trong cột Ghi chú.

Sheet Phân quyền
